<?xml version="1.0"?>
<robot name="luxshare_robot" xmlns:xacro="http://ros.org/wiki/xacro">
    <xacro:arg name="camera_name"   default="oak" />
    <xacro:arg name="camera_model"  default="OAK-D" />
    <xacro:arg name="base_frame"    default="oak-d_frame" />
    <xacro:arg name="parent_frame"  default="panel_link" />
    <xacro:arg name="cam_pos_x"     default="0.0" />
    <xacro:arg name="cam_pos_y"     default="0.0" />
    <xacro:arg name="cam_pos_z"     default="0.0" />
    <xacro:arg name="cam_roll"      default="0.0" />
    <xacro:arg name="cam_pitch"     default="0.0" />
    <xacro:arg name="cam_yaw"       default="0.0" />

    <xacro:include filename="$(find robot_description)/urdf/include/depthai_macro.urdf.xacro"/>

    <!-- <link name="$(arg parent_frame)"/> -->
    <xacro:depthai_camera camera_name = "$(arg camera_name)" parent = "$(arg parent_frame)" camera_model = "$(arg camera_model)" base_frame = "$(arg base_frame)" cam_pos_x = "$(arg cam_pos_x)" cam_pos_y = "$(arg cam_pos_y)" cam_pos_z = "$(arg cam_pos_z)" cam_roll = "$(arg cam_roll)" cam_pitch = "$(arg cam_pitch)" cam_yaw = "$(arg cam_yaw)"/>

    <link name="base_footprint"/>

    <joint name="base_joint" type="fixed">
        <parent link="base_footprint"/>
        <child link="base_link"/>
        <origin xyz="0.14 0.0 0.085" rpy="0 0 0"/>
    </joint>

    <link name="base_link">
        <visual>
            <origin xyz=" 0.0 0 0.00" rpy="0 0 0" />
            <geometry>
                <box size="0.375 0.28 0.09"/>
            </geometry>
            <material name="red">
                <color rgba="1 0 0 1"/>
            </material>
        </visual>
        <collision>
            <origin xyz=" 0.14 0 0.085" rpy="0 0 0" />
            <geometry>
                <box size="0.375 0.28 0.09"/>
            </geometry>
            <material name="red">
                <color rgba="1 0 0 1"/>
            </material>    
        </collision>
        <inertial>
            <mass value="0.2"/>
            <inertia ixx="0.1239375" ixy="0" ixz="0" iyy="0.18252083" iyz="0" izz="0.07208333"/>
        </inertial>
    </link>   

    <!-- pillar joint -->
    <link name="panel_link">
        <visual>
        <origin xyz="0.0875 -0.09 0.005" rpy="0 0 0"/>
        <geometry>
            <box size="0.21 0.21 0.01"/>
        </geometry>
        <material name="black">
            <color rgba="0.0 0.0 0.0 1" /> 
        </material>
        </visual>
        <collision>
            <origin xyz=" 0.0875 -0.09 0.005" rpy="0 0 0" />
            <geometry>
                <box size="0.21 0.21 0.01"/>
            </geometry>
            <material name="black">
                <color rgba="0 0 0 1"/>
            </material>    
        </collision>
        <inertial>
            <mass value="0.3"/>
            <inertia ixx="0.1239375" ixy="0" ixz="0" iyy="0.18252083" iyz="0" izz="0.07208333"/>
        </inertial>
    </link>

    <link name="pillar_l_link">
        <visual>
        <origin xyz="0 0 0.095" rpy="0 0 0"/>
        <geometry>
            <box size="0.035 0.03 0.19"/>
        </geometry>
        <material name="black">
            <color rgba="0.0 0.0 0.0 1" /> 
        </material>
        </visual>
    </link>

    <link name="pillar_r_link">
        <visual>
        <origin xyz="0 0 0.095" rpy="0 0 0"/>
        <geometry>
            <box size="0.035 0.03 0.19"/>
        </geometry>
        <material name="black">
            <color rgba="0.0 0.0 0.0 1" /> 
        </material>
        </visual>
    </link>

    <joint name="pillar_dl_joint" type="fixed">
        <parent link="base_link" />
        <child link="pillar_l_link" />
        <origin xyz="-0.16 0.09 0.045" />
    </joint>

    <joint name="pillar_dr_joint" type="fixed">
        <parent link="base_link" />
        <child link="pillar_r_link" />
        <origin xyz="-0.16 -0.09 0.045" />
    </joint>

    <joint name="pillar_ul_joint" type="fixed">
        <parent link="pillar_l_link" />
        <child link="panel_link" />
        <origin xyz="0 0 0.19" />
    </joint>

    <!-- laser link -->
    <link name="laser_link">
        <visual>
        <origin xyz="0 0 0" rpy="0 0 0"/>
        <geometry>
            <cylinder length="0.02" radius="0.035"/>
        </geometry>
        <material name="black">
            <color rgba="0.0 0.0 0.0 0.5" /> 
        </material>
        </visual>
    </link>
    
    <!-- laser joint -->
    <joint name="laser_joint" type="fixed">
        <parent link="base_link" />
        <child link="laser_link" />
        <origin xyz="0.11 0 0.055" rpy="0 0 3.14"/>
    </joint>

    <link name="imu_link">
        <visual>
        <origin xyz="0 0 0.0" rpy="0 0 0"/>
        <geometry>
            <box size="0.02 0.02 0.02"/>
        </geometry>
        </visual>
    </link>

    <!-- imu joint -->
    <joint name="imu_joint" type="fixed">
        <parent link="base_link" />
        <child link="imu_link" />
        <origin xyz="-0.14 0 0.0" />
    </joint>

    <!-- <link name="odom_link">
        <visual>
        <origin xyz="0 0 0.0" rpy="0 0 0"/>
        <geometry>
            <box size="0.02 0.02 0.02"/>
        </geometry>
        </visual>
    </link>   

    <joint name="odom_joint" type="fixed">
        <parent link="base_link" />
        <child link="odom_link" />
        <origin xyz="-0.14 0.0 -0.035" />
    </joint> -->

    <joint name="left_wheel_joint" type="continuous">
        <origin xyz="-0.14 0.165 -0.035" rpy="1.57 0 0"/>
        <parent link="base_link"/>
        <child link="left_wheel_link"/>
        <axis xyz="0 0 -1"/>
    </joint>

    <link name="left_wheel_link">
        <visual>
            <origin xyz="0 0 0" rpy="0 0 0" />
            <geometry>
                <cylinder radius="0.05" length = "0.04"/>
            </geometry>
            <material name="black">
                <color rgba="0 0 0 1"/>
            </material>
        </visual>
        <collision>
            <origin xyz="0 0 0" rpy="0 0 0" />
            <geometry>
                <cylinder radius="0.05" length = "0.04"/>
            </geometry>
            <material name="black">
                <color rgba="0 0 0 1"/>
            </material>
        </collision>
        <inertial>
            <mass value="0.2"/>
        <inertia ixx="0.000190416666667" ixy="0" ixz="0" iyy="0.0001904" iyz="0" izz="0.00036"/>
        </inertial>
    </link>

    <joint name="right_wheel_joint" type="continuous">
        <origin xyz="-0.14 -0.165 -0.035" rpy="1.57 0 0"/>
        <parent link="base_link"/>
        <child link="right_wheel_link"/>
        <axis xyz="0 0 -1"/>
    </joint>

    <link name="right_wheel_link">
        <visual>
            <origin xyz="0 0 0" rpy="0 0 0" />
            <geometry>
                <cylinder radius="0.05" length = "0.04"/>
            </geometry>
            <material name="black">
                <color rgba="0 0 0 1"/>
            </material>
        </visual>
        <collision>
            <origin xyz="0 0 0" rpy="0 0 0" />
            <geometry>
                <cylinder radius="0.05" length = "0.04"/>
            </geometry>
            <material name="black">
                <color rgba="0 0 0 1"/>
            </material>
        </collision>
        <inertial>
            <mass value="0.2"/>
        <inertia ixx="0.000190416666667" ixy="0" ixz="0" iyy="0.0001904" iyz="0" izz="0.00036"/>
        </inertial>
    </link>

    <joint name="front_wheel_joint" type="fixed">
        <origin xyz="0.09 0 -0.035" rpy="1.57 0 0"/>
        <parent link="base_link"/>
        <child link="front_wheel_link"/>
        <axis xyz="0 0 1"/>
    </joint>

    <link name="front_wheel_link">
        <visual>
            <origin xyz="0 0 0" rpy="0 0 0" />
            <geometry>
                <cylinder radius="0.05" length = "0.04"/>
            </geometry>
            <material name="black">
                <color rgba="0 0 0 1"/>
            </material>
        </visual>
        <collision>
            <origin xyz="0 0 0" rpy="0 0 0" />
            <geometry>
                <cylinder radius="0.05" length = "0.04"/>
            </geometry>
            <material name="black">
                <color rgba="0 0 0 1"/>
            </material>
        </collision>
        <inertial>
            <mass value="0.02"/>
      <inertia ixx="0.000190416666667" ixy="0" ixz="0" iyy="0.0001904" iyz="0" izz="0.00036"/>
    </inertial>
    </link>

</robot>