<?xml version="1.0" ?>
<robot name="luxshare_robot" xmlns:xacro="http://www.ros.org/wiki/xacro">

    <link name="base_footprint"/>

    <joint name="base_joint" type="fixed">
        <parent link="base_footprint"/>
        <child link="base_link"/>
        <origin xyz="0.14 0.0 0.085" rpy="0 0 0"/>
    </joint>

    <link name="base_link">
        <visual>
            <origin xyz=" 0.0 0 0.00" rpy="0 0 0" />
            <geometry>
                <box size="0.375 0.28 0.09"/>
            </geometry>
            <material name="red">
                <color rgba="1 0 0 1"/>
            </material>
        </visual>
        <collision>
            <origin xyz=" 0.14 0 0.085" rpy="0 0 0" />
            <geometry>
                <box size="0.375 0.28 0.09"/>
            </geometry>
            <material name="red">
                <color rgba="1 0 0 1"/>
            </material>    
        </collision>
        <inertial>
            <mass value="0.2"/>
            <inertia ixx="0.1239375" ixy="0" ixz="0" iyy="0.18252083" iyz="0" izz="0.07208333"/>
        </inertial>
    </link>   

    <!-- pillar joint -->
    <link name="panel_link">
        <visual>
            <origin xyz="0.0875 -0.09 0.005" rpy="0 0 0"/>
            <geometry>
                <box size="0.21 0.21 0.01"/>
            </geometry>
            <material name="black">
                <color rgba="0.0 0.0 0.0 1" /> 
            </material>
        </visual>
        <collision>
            <origin xyz=" 0.0875 -0.09 0.005" rpy="0 0 0" />
            <geometry>
                <box size="0.21 0.21 0.01"/>
            </geometry>
            <material name="black">
                <color rgba="0 0 0 1"/>
            </material>    
        </collision>
        <inertial>
            <mass value="0.3"/>
            <inertia ixx="0.1239375" ixy="0" ixz="0" iyy="0.18252083" iyz="0" izz="0.07208333"/>
        </inertial>
    </link>

    <link name="pillar_l_link">
        <visual>
        <origin xyz="0 0 0.095" rpy="0 0 0"/>
        <geometry>
            <box size="0.035 0.03 0.19"/>
        </geometry>
        <material name="black">
            <color rgba="0.0 0.0 0.0 1" /> 
        </material>
        </visual>
    </link>

    <link name="pillar_r_link">
        <visual>
        <origin xyz="0 0 0.095" rpy="0 0 0"/>
        <geometry>
            <box size="0.035 0.03 0.19"/>
        </geometry>
        <material name="black">
            <color rgba="0.0 0.0 0.0 1" /> 
        </material>
        </visual>
    </link>

    <joint name="pillar_dl_joint" type="fixed">
        <parent link="base_link" />
        <child link="pillar_l_link" />
        <origin xyz="-0.16 0.09 0.045" />
    </joint>

    <joint name="pillar_dr_joint" type="fixed">
        <parent link="base_link" />
        <child link="pillar_r_link" />
        <origin xyz="-0.16 -0.09 0.045" />
    </joint>

    <joint name="pillar_ul_joint" type="fixed">
        <parent link="pillar_l_link" />
        <child link="panel_link" />
        <origin xyz="0 0 0.19" />
    </joint>

    <!-- laser link -->
    <link name="laser_link">
        <visual>
        <origin xyz="0 0 0" rpy="0 0 0"/>
        <geometry>
            <cylinder length="0.02" radius="0.035"/>
        </geometry>
        <material name="black">
            <color rgba="0.0 0.0 0.0 0.5" /> 
        </material>
        </visual>
    </link>
    
    <!-- laser joint -->
    <joint name="laser_joint" type="fixed">
        <parent link="base_link" />
        <child link="laser_link" />
        <origin xyz="0.11 0 0.055" rpy="0 0 0"/>
    </joint>

    <link name="imu_link">
        <visual>
        <origin xyz="0 0 0.0" rpy="0 0 0"/>
        <geometry>
            <box size="0.02 0.02 0.02"/>
        </geometry>
        </visual>
    </link>

    <!-- imu joint -->
    <joint name="imu_joint" type="fixed">
        <parent link="base_link" />
        <child link="imu_link" />
        <origin xyz="-0.14 0 0.0" />
    </joint>


    <joint name="left_wheel_joint" type="continuous">
        <origin xyz="-0.14 0.165 -0.035" rpy="1.57 0 0"/>
        <parent link="base_link"/>
        <child link="left_wheel_link"/>
        <axis xyz="0 0 -1"/>
    </joint>

    <link name="left_wheel_link">
        <visual>
            <origin xyz="0 0 0" rpy="0 0 0" />
            <geometry>
                <cylinder radius="0.05" length = "0.04"/>
            </geometry>
            <material name="black">
                <color rgba="0 0 0 1"/>
            </material>
        </visual>
        <collision>
            <origin xyz="0 0 0" rpy="0 0 0" />
            <geometry>
                <cylinder radius="0.05" length = "0.04"/>
            </geometry>
            <material name="black">
                <color rgba="0 0 0 1"/>
            </material>
        </collision>
        <inertial>
            <mass value="0.2"/>
        <inertia ixx="0.000190416666667" ixy="0" ixz="0" iyy="0.0001904" iyz="0" izz="0.00036"/>
        </inertial>
    </link>

    <joint name="right_wheel_joint" type="continuous">
        <origin xyz="-0.14 -0.165 -0.035" rpy="1.57 0 0"/>
        <parent link="base_link"/>
        <child link="right_wheel_link"/>
        <axis xyz="0 0 -1"/>
    </joint>

    <link name="right_wheel_link">
        <visual>
            <origin xyz="0 0 0" rpy="0 0 0" />
            <geometry>
                <cylinder radius="0.05" length = "0.04"/>
            </geometry>
            <material name="black">
                <color rgba="0 0 0 1"/>
            </material>
        </visual>
        <collision>
            <origin xyz="0 0 0" rpy="0 0 0" />
            <geometry>
                <cylinder radius="0.05" length = "0.04"/>
            </geometry>
            <material name="black">
                <color rgba="0 0 0 1"/>
            </material>
        </collision>
        <inertial>
            <mass value="0.2"/>
        <inertia ixx="0.000190416666667" ixy="0" ixz="0" iyy="0.0001904" iyz="0" izz="0.00036"/>
        </inertial>
    </link>

    <joint name="front_wheel_joint" type="fixed">
        <origin xyz="0.09 0 -0.035" rpy="1.57 0 0"/>
        <parent link="base_link"/>
        <child link="front_wheel_link"/>
        <axis xyz="0 0 1"/>
    </joint>

    <link name="front_wheel_link">
        <visual>
            <origin xyz="0 0 0" rpy="0 0 0" />
            <geometry>
                <cylinder radius="0.05" length = "0.04"/>
            </geometry>
            <material name="black">
                <color rgba="0 0 0 1"/>
            </material>
        </visual>
        <collision>
            <origin xyz="0 0 0" rpy="0 0 0" />
            <geometry>
                <cylinder radius="0.05" length = "0.04"/>
            </geometry>
            <material name="black">
                <color rgba="0 0 0 1"/>
            </material>
        </collision>
        <inertial>
            <mass value="0.02"/>
      <inertia ixx="0.000190416666667" ixy="0" ixz="0" iyy="0.0001904" iyz="0" izz="0.00036"/>
    </inertial>
    </link>

    <!-- <gazebo>
        <plugin name='diff_drive' filename='libgazebo_ros_diff_drive.so'>
            <ros>
                <namespace>/</namespace>
                <remapping>cmd_vel:=cmd_vel</remapping>
                <remapping>odom:=odom</remapping>
            </ros>
            <update_rate>30</update_rate>
             
            <left_joint>left_wheel_joint</left_joint>
            <right_joint>right_wheel_joint</right_joint>
             
            <wheel_separation>0.32</wheel_separation>
            <wheel_diameter>0.1</wheel_diameter>
             
            <max_wheel_torque>20</max_wheel_torque>
            <max_wheel_acceleration>1.0</max_wheel_acceleration>
            
            <publish_odom>true</publish_odom>
            <publish_odom_tf>true</publish_odom_tf>
            <publish_wheel_tf>true</publish_wheel_tf>
            <odometry_frame>odom</odometry_frame>
           
            <robot_base_frame>base_footprint</robot_base_frame>
        </plugin>
    </gazebo>  -->

    <gazebo reference="left_wheel_link">
        <material>Gazebo/Black</material>
    </gazebo>

    <gazebo reference="right_wheel_link">
        <material>Gazebo/Black</material>
    </gazebo>

    <gazebo reference="front_wheel_link">
        <material>Gazebo/Black</material>
    </gazebo>

    <gazebo reference="front_wheel_link">
        <mu1 value="0.0"/>
        <mu2 value="0.0"/>
        <kp value="1000000.0" />
        <kd value="10.0" />
    </gazebo>

    <gazebo reference="laser_link">
        <sensor name="laser_sensor" type="ray">
        <always_on>true</always_on>
        <visualize>true</visualize>
        <update_rate>10</update_rate>
        <!-- <pose>0 0 0 0 0 0</pose> -->
        <ray>
            <scan>
                <horizontal>
                <samples>360</samples>
                <resolution>1.000000</resolution>
                <min_angle>0.000000</min_angle>
                <max_angle>6.280000</max_angle>
                </horizontal>
            </scan>
            <range>
                <min>0.30000</min>
                <max>10.0</max>
                <resolution>0.02000</resolution>
            </range>
            <noise>
                <type>gaussian</type>
                <mean>0.0</mean>
                <stddev>0.065</stddev>
            </noise>
        </ray>

        <plugin name="laserscan" filename="libgazebo_ros_ray_sensor.so">
            <ros>
            <remapping>~/out:=scan</remapping>
            </ros>
            <output_type>sensor_msgs/LaserScan</output_type>
            <frame_name>laser_link</frame_name>
        </plugin>
        </sensor>
    </gazebo>

    <gazebo reference="imu_link">
        <sensor name="imu_sensor" type="imu">
        <plugin filename="libgazebo_ros_imu_sensor.so" name="imu_plugin">
            <ros>
                <namespace>/</namespace>
                <remapping>~/out:=imu</remapping>
            </ros>
            <frame_name>imu_link</frame_name>
            <initial_orientation_as_reference>false</initial_orientation_as_reference>
            </plugin>
            <always_on>true</always_on>
            <update_rate>100</update_rate>
            <visualize>true</visualize>
            <imu>
            <angular_velocity>
                <x>
                <noise type="gaussian">
                    <mean>0.0</mean>
                    <stddev>2e-4</stddev>
                    <bias_mean>0.0000075</bias_mean>
                    <bias_stddev>0.0000008</bias_stddev>
                </noise>
                </x>
                <y>
                <noise type="gaussian">
                    <mean>0.0</mean>
                    <stddev>2e-4</stddev>
                    <bias_mean>0.0000075</bias_mean>
                    <bias_stddev>0.0000008</bias_stddev>
                </noise>
                </y>
                <z>
                <noise type="gaussian">
                    <mean>0.0</mean>
                    <stddev>2e-4</stddev>
                    <bias_mean>0.0000075</bias_mean>
                    <bias_stddev>0.0000008</bias_stddev>
                </noise>
                </z>
            </angular_velocity>
            <linear_acceleration>
                <x>
                <noise type="gaussian">
                    <mean>0.0</mean>
                    <stddev>1.7e-2</stddev>
                    <bias_mean>0.1</bias_mean>
                    <bias_stddev>0.001</bias_stddev>
                </noise>
                </x>
                <y>
                <noise type="gaussian">
                    <mean>0.0</mean>
                    <stddev>1.7e-2</stddev>
                    <bias_mean>0.1</bias_mean>
                    <bias_stddev>0.001</bias_stddev>
                </noise>
                </y>
                <z>
                <noise type="gaussian">
                    <mean>0.0</mean>
                    <stddev>1.7e-2</stddev>
                    <bias_mean>0.1</bias_mean>
                    <bias_stddev>0.001</bias_stddev>
                </noise>
                </z>
            </linear_acceleration>
            </imu>
        </sensor>
    </gazebo>

    <gazebo>
        <plugin name="p3d_base_controller" filename="libgazebo_ros_p3d.so">
            <ros>
                <namespace>gazebo_p3d</namespace>
                <remapping>odom:=ground_truth/pose</remapping>
            </ros>
            <frame_name>world</frame_name>
            <body_name>base_footprint</body_name>
            <update_rate>50.0</update_rate>
            <gaussian_noise>0.0</gaussian_noise>
            <xyz_offset>0 0 0</xyz_offset>
            <rpy_offset>0 0 0</rpy_offset>
        </plugin>
    </gazebo>

    <ros2_control name="GazeboSystem" type="system">
        <hardware>
            <plugin>gazebo_ros2_control/GazeboSystem</plugin>
        </hardware>
        <joint name="left_wheel_joint">
            <command_interface name="velocity">
            <param name="min">-1</param>
            <param name="max">1</param>
            </command_interface>
            <state_interface name="position"/>
            <state_interface name="velocity"/>
        </joint>
        <joint name="right_wheel_joint">
            <command_interface name="velocity">
            <param name="min">-1</param>
            <param name="max">1</param>
            </command_interface>
            <state_interface name="position"/>
            <state_interface name="velocity"/>
        </joint>
    </ros2_control>

    <gazebo>
        <!-- Joint state publisher -->
        <plugin filename="libgazebo_ros2_control.so" name="gazebo_ros2_control">
            <ros>
                <namespace>/</namespace>
                <remapping>/diff_drive_base_controller/cmd_vel_unstamped:=cmd_vel</remapping>
                <remapping>/diff_drive_base_controller/odom:=wheel_odom</remapping>
            </ros>
            <parameters>$(find robot_description)/config/diff_robot_controller.yaml</parameters>
        </plugin>
    </gazebo>

</robot>